Workbook

Sheet Summary
A1: Master Test Cases
A2: Selenium + TestNG + Java, Page Object Model on the VOID runtime. Counts below are formulas over the Test Cases sheet.
A4: Applications | B4: SauceDemo (https://www.saucedemo.com), DemoQA (https://demoqa.com)
A5: Run everything | B5: mvn clean test "-Dsurefire.suiteXmlFiles=src/testNgXml/examples.xml"
A6: Headless | B6: add -Dheadless=true
A7: Extent report | B7: logs/extent-report/ExamplesSuite.html
A8: Last automated run | B8: 2026-10-28T15:21:39 IST
A10: By application
A11: Application | B11: Total cases | C11: Automated | D11: Manual only | E11: Manual: Pass | F11: Manual: Fail | G11: Manual: Not run | H11: Automated: Pass
A12: SauceDemo | B12: =COUNTIF('Test Cases'!$B$4:$B$68,"SauceDemo") | C12: =COUNTIFS('Test Cases'!$B$4:$B$68,"SauceDemo",'Test Cases'!$N$4:$N$68,"Yes") | D12: =COUNTIFS('Test Cases'!$B$4:$B$68,"SauceDemo",'Test Cases'!$N$4:$N$68,"No") | E12: =COUNTIFS('Test Cases'!$B$4:$B$68,"SauceDemo",'Test Cases'!$K$4:$K$68,"Pass*") | F12: =COUNTIFS('Test Cases'!$B$4:$B$68,"SauceDemo",'Test Cases'!$K$4:$K$68,"Fail*") | G12: =COUNTIFS('Test Cases'!$B$4:$B$68,"SauceDemo",'Test Cases'!$K$4:$K$68,"Not*") | H12: =COUNTIFS('Test Cases'!$B$4:$B$68,"SauceDemo",'Test Cases'!$P$4:$P$68,"Pass*")
A13: DemoQA | B13: =COUNTIF('Test Cases'!$B$4:$B$68,"DemoQA") | C13: =COUNTIFS('Test Cases'!$B$4:$B$68,"DemoQA",'Test Cases'!$N$4:$N$68,"Yes") | D13: =COUNTIFS('Test Cases'!$B$4:$B$68,"DemoQA",'Test Cases'!$N$4:$N$68,"No") | E13: =COUNTIFS('Test Cases'!$B$4:$B$68,"DemoQA",'Test Cases'!$K$4:$K$68,"Pass*") | F13: =COUNTIFS('Test Cases'!$B$4:$B$68,"DemoQA",'Test Cases'!$K$4:$K$68,"Fail*") | G13: =COUNTIFS('Test Cases'!$B$4:$B$68,"DemoQA",'Test Cases'!$K$4:$K$68,"Not*") | H13: =COUNTIFS('Test Cases'!$B$4:$B$68,"DemoQA",'Test Cases'!$P$4:$P$68,"Pass*")
A14: Total | B14: =SUM(B12:B13) | C14: =SUM(C12:C13) | D14: =SUM(D12:D13) | E14: =SUM(E12:E13) | F14: =SUM(F12:F13) | G14: =SUM(G12:G13) | H14: =SUM(H12:H13)
A16: By module
A17: Module | B17: Application | C17: Total cases | D17: Automated | E17: Manual: Pass | F17: Manual: Fail | G17: Manual: Not run | H17: Automated: Pass
A18: Login | B18: SauceDemo | C18: =COUNTIF('Test Cases'!$C$4:$C$68,"Login") | D18: =COUNTIFS('Test Cases'!$C$4:$C$68,"Login",'Test Cases'!$N$4:$N$68,"Yes") | E18: =COUNTIFS('Test Cases'!$C$4:$C$68,"Login",'Test Cases'!$K$4:$K$68,"Pass*") | F18: =COUNTIFS('Test Cases'!$C$4:$C$68,"Login",'Test Cases'!$K$4:$K$68,"Fail*") | G18: =COUNTIFS('Test Cases'!$C$4:$C$68,"Login",'Test Cases'!$K$4:$K$68,"Not*") | H18: =COUNTIFS('Test Cases'!$C$4:$C$68,"Login",'Test Cases'!$P$4:$P$68,"Pass*")
A19: Landing Page | B19: SauceDemo | C19: =COUNTIF('Test Cases'!$C$4:$C$68,"Landing Page") | D19: =COUNTIFS('Test Cases'!$C$4:$C$68,"Landing Page",'Test Cases'!$N$4:$N$68,"Yes") | E19: =COUNTIFS('Test Cases'!$C$4:$C$68,"Landing Page",'Test Cases'!$K$4:$K$68,"Pass*") | F19: =COUNTIFS('Test Cases'!$C$4:$C$68,"Landing Page",'Test Cases'!$K$4:$K$68,"Fail*") | G19: =COUNTIFS('Test Cases'!$C$4:$C$68,"Landing Page",'Test Cases'!$K$4:$K$68,"Not*") | H19: =COUNTIFS('Test Cases'!$C$4:$C$68,"Landing Page",'Test Cases'!$P$4:$P$68,"Pass*")
A20: Cart & Checkout | B20: SauceDemo | C20: =COUNTIF('Test Cases'!$C$4:$C$68,"Cart & Checkout") | D20: =COUNTIFS('Test Cases'!$C$4:$C$68,"Cart & Checkout",'Test Cases'!$N$4:$N$68,"Yes") | E20: =COUNTIFS('Test Cases'!$C$4:$C$68,"Cart & Checkout",'Test Cases'!$K$4:$K$68,"Pass*") | F20: =COUNTIFS('Test Cases'!$C$4:$C$68,"Cart & Checkout",'Test Cases'!$K$4:$K$68,"Fail*") | G20: =COUNTIFS('Test Cases'!$C$4:$C$68,"Cart & Checkout",'Test Cases'!$K$4:$K$68,"Not*") | H20: =COUNTIFS('Test Cases'!$C$4:$C$68,"Cart & Checkout",'Test Cases'!$P$4:$P$68,"Pass*")
A21: Practice Form | B21: DemoQA | C21: =COUNTIF('Test Cases'!$C$4:$C$68,"Practice Form") | D21: =COUNTIFS('Test Cases'!$C$4:$C$68,"Practice Form",'Test Cases'!$N$4:$N$68,"Yes") | E21: =COUNTIFS('Test Cases'!$C$4:$C$68,"Practice Form",'Test Cases'!$K$4:$K$68,"Pass*") | F21: =COUNTIFS('Test Cases'!$C$4:$C$68,"Practice Form",'Test Cases'!$K$4:$K$68,"Fail*") | G21: =COUNTIFS('Test Cases'!$C$4:$C$68,"Practice Form",'Test Cases'!$K$4:$K$68,"Not*") | H21: =COUNTIFS('Test Cases'!$C$4:$C$68,"Practice Form",'Test Cases'!$P$4:$P$68,"Pass*")
A22: Select Menu | B22: DemoQA | C22: =COUNTIF('Test Cases'!$C$4:$C$68,"Select Menu") | D22: =COUNTIFS('Test Cases'!$C$4:$C$68,"Select Menu",'Test Cases'!$N$4:$N$68,"Yes") | E22: =COUNTIFS('Test Cases'!$C$4:$C$68,"Select Menu",'Test Cases'!$K$4:$K$68,"Pass*") | F22: =COUNTIFS('Test Cases'!$C$4:$C$68,"Select Menu",'Test Cases'!$K$4:$K$68,"Fail*") | G22: =COUNTIFS('Test Cases'!$C$4:$C$68,"Select Menu",'Test Cases'!$K$4:$K$68,"Not*") | H22: =COUNTIFS('Test Cases'!$C$4:$C$68,"Select Menu",'Test Cases'!$P$4:$P$68,"Pass*")
A23: Upload and Download | B23: DemoQA | C23: =COUNTIF('Test Cases'!$C$4:$C$68,"Upload and Download") | D23: =COUNTIFS('Test Cases'!$C$4:$C$68,"Upload and Download",'Test Cases'!$N$4:$N$68,"Yes") | E23: =COUNTIFS('Test Cases'!$C$4:$C$68,"Upload and Download",'Test Cases'!$K$4:$K$68,"Pass*") | F23: =COUNTIFS('Test Cases'!$C$4:$C$68,"Upload and Download",'Test Cases'!$K$4:$K$68,"Fail*") | G23: =COUNTIFS('Test Cases'!$C$4:$C$68,"Upload and Download",'Test Cases'!$K$4:$K$68,"Not*") | H23: =COUNTIFS('Test Cases'!$C$4:$C$68,"Upload and Download",'Test Cases'!$P$4:$P$68,"Pass*")
A24: Buttons | B24: DemoQA | C24: =COUNTIF('Test Cases'!$C$4:$C$68,"Buttons") | D24: =COUNTIFS('Test Cases'!$C$4:$C$68,"Buttons",'Test Cases'!$N$4:$N$68,"Yes") | E24: =COUNTIFS('Test Cases'!$C$4:$C$68,"Buttons",'Test Cases'!$K$4:$K$68,"Pass*") | F24: =COUNTIFS('Test Cases'!$C$4:$C$68,"Buttons",'Test Cases'!$K$4:$K$68,"Fail*") | G24: =COUNTIFS('Test Cases'!$C$4:$C$68,"Buttons",'Test Cases'!$K$4:$K$68,"Not*") | H24: =COUNTIFS('Test Cases'!$C$4:$C$68,"Buttons",'Test Cases'!$P$4:$P$68,"Pass*")
A25: Check Box | B25: DemoQA | C25: =COUNTIF('Test Cases'!$C$4:$C$68,"Check Box") | D25: =COUNTIFS('Test Cases'!$C$4:$C$68,"Check Box",'Test Cases'!$N$4:$N$68,"Yes") | E25: =COUNTIFS('Test Cases'!$C$4:$C$68,"Check Box",'Test Cases'!$K$4:$K$68,"Pass*") | F25: =COUNTIFS('Test Cases'!$C$4:$C$68,"Check Box",'Test Cases'!$K$4:$K$68,"Fail*") | G25: =COUNTIFS('Test Cases'!$C$4:$C$68,"Check Box",'Test Cases'!$K$4:$K$68,"Not*") | H25: =COUNTIFS('Test Cases'!$C$4:$C$68,"Check Box",'Test Cases'!$P$4:$P$68,"Pass*")
A27: Legend
A28: Manual Status | B28: Result of executing the case by hand. "Fail" marks a product defect (see Defects).
A29: Last Automated Result | B29: From target/surefire-reports/testng-results.xml of the last run. "Pass (defect anchor)" means the test asserts the current defective behavior so a fix or regression is flagged.
A30: Severity / Priority | B30: Severity: impact on the user (Critical, High, Medium, Low). Priority: order to fix or run (P1 highest).

Sheet Test Cases
A1: Master Test Cases: SauceDemo and DemoQA
A2: Manual test cases for both applications, with the automated test that covers each one and its result from the last suite run.
A3: Test ID | B3: Application | C3: Module | D3: Component | E3: Precondition | F3: Description | G3: Detailed Steps | H3: Test Data | I3: Expected Result | J3: Actual Result | K3: Manual Status | L3: Severity | M3: Priority | N3: Automated | O3: Automation Method | P3: Last Automated Result | Q3: Notes
A4: LOGIN-01 | B4: SauceDemo | C4: Login | D4: Text input, button | E4: Browser open, navigated to https://www.saucedemo.com/, login page loaded | F4: Valid login | G4: 1. Enter username in Username field. 2. Enter password in Password field. 3. Click Login button. | H4: standard_user / secret_sauce | I4: User is authenticated and redirected to Products page (inventory.html) | J4: Redirected to inventory.html, products listed correctly | K4: Pass | L4: Critical | M4: P1 | N4: Yes | O4: SauceDemoTest.login01_validLogin | P4: Pass
A5: LOGIN-02 | B5: SauceDemo | C5: Login | D5: Text input, button | E5: Browser open, login page loaded, fields empty | F5: Empty username & password validation | G5: 1. Leave Username and Password fields blank. 2. Click Login button without entering anything. | H5: (blank) / (blank) | I5: Error message indicating username is required is displayed | J5: Epic sadface: Username is required | K5: Pass | L5: Medium | M5: P2 | N5: Yes | O5: SauceDemoTest.login02_emptyCredentials | P5: Pass
A6: LOGIN-03 | B6: SauceDemo | C6: Login | D6: Text input, button | E6: Browser open, login page loaded | F6: Empty password validation | G6: 1. Enter username only. 2. Leave Password blank. 3. Click Login. | H6: standard_user / (blank) | I6: Error message indicating password is required is displayed | J6: Epic sadface: Password is required | K6: Pass | L6: Medium | M6: P2 | N6: Yes | O6: SauceDemoTest.login03_emptyPassword | P6: Pass
A7: LOGIN-04 | B7: SauceDemo | C7: Login | D7: Text input, button | E7: Browser open, login page loaded | F7: Empty username validation | G7: 1. Leave Username blank. 2. Enter password only. 3. Click Login. | H7: (blank) / secret_sauce | I7: Error message indicating username is required is displayed (takes priority over password check) | J7: Epic sadface: Username is required | K7: Pass | L7: Medium | M7: P2 | N7: Yes | O7: SauceDemoTest.login04_emptyUsername | P7: Pass | Q7: Username check takes priority when both invalid
A8: LOGIN-05 | B8: SauceDemo | C8: Login | D8: Text input, button | E8: Browser open, login page loaded | F8: Invalid username/password combination | G8: 1. Enter a valid username with an incorrect password. 2. Click Login. | H8: standard_user / wrongpass | I8: Generic authentication error is shown without revealing which field is incorrect | J8: Epic sadface: Username and password do not match any user in this service | K8: Pass | L8: High | M8: P1 | N8: Yes | O8: SauceDemoTest.login05_invalidCredentials | P8: Pass
A9: LOGIN-06 | B9: SauceDemo | C9: Login | D9: Text input, button | E9: Browser open, login page loaded | F9: Locked out user login attempt | G9: 1. Enter locked_out_user credentials. 2. Click Login. | H9: locked_out_user / secret_sauce | I9: Access denied with a specific lockout message | J9: Epic sadface: Sorry, this user has been locked out. | K9: Pass | L9: High | M9: P1 | N9: Yes | O9: SauceDemoTest.login06_lockedOutUser | P9: Pass
A10: LOGIN-07 | B10: SauceDemo | C10: Login | D10: Text input, button | E10: Browser open, login page loaded | F10: Username case sensitivity check | G10: 1. Enter username with altered casing. 2. Enter correct password. 3. Click Login. | H10: Standard_User / secret_sauce | I10: Login should fail since usernames are case-sensitive | J10: Failed with 'do not match' error - confirmed case-sensitive | K10: Pass | L10: Medium | M10: P3 | N10: Yes | O10: SauceDemoTest.login07_usernameCaseSensitive | P10: Pass
A11: LOGIN-08 | B11: SauceDemo | C11: Login | D11: Text input, button | E11: Browser open, login page loaded | F11: Leading/trailing whitespace handling | G11: 1. Enter username with extra leading and trailing spaces. 2. Enter correct password. 3. Click Login. | H11: ' standard_user ' / secret_sauce | I11: Login should fail unless whitespace is trimmed by the app | J11: Failed with 'do not match' error - whitespace not trimmed | K11: Pass (expected behavior) | L11: Low | M11: P3 | N11: Yes | O11: SauceDemoTest.login08_leadingTrailingWhitespace | P11: Pass | Q11: Whitespace not trimmed - acceptable for this demo app
A12: LOGIN-09 | B12: SauceDemo | C12: Login | D12: Text input, button | E12: Browser open, login page loaded | F12: SQL injection / script injection attempt | G12: 1. Enter SQL injection string in Username field. 2. Enter script injection string in Password field. 3. Click Login. | H12: ' OR '1'='1 / <script>alert(1)</script> | I12: No script execution or injection bypass; generic invalid-credentials error shown | J12: No script executed, generic 'do not match' error shown - no vulnerability found | K12: Pass | L12: Critical | M12: P1 | N12: Yes | O12: SauceDemoTest.login09_injectionAttempt | P12: Pass | Q12: No security vulnerability observed in this basic test
A13: LOGIN-10 | B13: SauceDemo | C13: Login | D13: Password input | E13: Browser open, login page loaded | F13: Password field masking | G13: 1. Click into Password field. 2. Type a password. | H13: any / secret_sauce | I13: Characters are masked/hidden as dots, not shown in plain text | J13: Confirmed masked display (type=password) | K13: Pass | L13: Medium | M13: P2 | N13: Yes | O13: SauceDemoTest.login10_passwordFieldMasked | P13: Pass
A14: LOGIN-11 | B14: SauceDemo | C14: Login | D14: Text input, button | E14: Browser open, login page loaded | F14: Alternate valid user type login | G14: 1. Enter problem_user credentials. 2. Click Login. | H14: problem_user / secret_sauce | I14: User authenticates successfully and is redirected to Products page | J14: Redirected successfully to inventory.html | K14: Pass | L14: High | M14: P2 | N14: Yes | O14: SauceDemoTest.login11_problemUser | P14: Pass | Q14: Known product-page display bugs for this user are out of scope for login testing
A15: LOGIN-12 | B15: SauceDemo | C15: Login | D15: Button (error dismiss icon) | E15: Browser open, login page loaded, an error message is currently displayed | F15: Error message dismissal via close icon | G15: 1. Trigger any login error. 2. Click the 'X' icon on the red error banner. | H15: any invalid combination | I15: Error banner closes/disappears from view | J15: Not fully verified visually in this test pass | K15: Not tested | L15: Low | M15: P3 | N15: Yes | O15: SauceDemoTest.login12_errorDismissal | P15: Pass | Q15: Recommend retesting explicitly with before/after screenshot
A16: LOGIN-13 | B16: SauceDemo | C16: Login | D16: Button | E16: Browser open, login page loaded, fields empty | F16: Login button always enabled (no client-side disable) | G16: 1. Observe Login button state with empty fields. 2. Click it. | H16: (blank fields) | I16: Button remains clickable regardless of field state; validation happens on submit, not via disabling the button | J16: Confirmed - button always enabled, validation occurs after click | K16: Pass | L16: Low | M16: P3 | N16: Yes | O16: SauceDemoTest.login13_loginButtonAlwaysEnabled | P16: Pass
A17: LAND-01 | B17: SauceDemo | C17: Landing Page | D17: Page load, product list | E17: User has valid credentials and is on the login page | F17: Landing page loads after login | G17: 1. Go to saucedemo.com. 2. Login with standard_user/secret_sauce. 3. Observe resulting page. | H17: standard_user / secret_sauce | I17: URL changes to /inventory.html; header 'Swag Labs', 'Products' title, sort dropdown, 6 product cards (image, name, description, price, Add to cart), and footer with social icons & copyright are all visible | J17: All elements loaded correctly as expected | K17: Pass | L17: Critical | M17: P1 | N17: Yes | O17: SauceDemoTest.land01_productsPageLoads | P17: Pass
A18: LAND-02 | B18: SauceDemo | C18: Landing Page | D18: Dropdown (sort) | E18: User logged in, on Products page, default sort active | F18: Sort by Name (A to Z) - default | G18: 1. On Products page, confirm dropdown shows 'Name (A to Z)' by default. | H18: N/A | I18: Products listed alphabetically: Backpack, Bike Light, Bolt T-Shirt, Fleece Jacket, Onesie, Test.allTheThings() T-Shirt | J18: Order matched alphabetical A-Z | K18: Pass | L18: Medium | M18: P2 | N18: Yes | O18: SauceDemoTest.land02_defaultSortAtoZ | P18: Pass
A19: LAND-03 | B19: SauceDemo | C19: Landing Page | D19: Dropdown (sort) | E19: User logged in, on Products page | F19: Sort by Name (Z to A) | G19: 1. Click sort dropdown. 2. Select 'Name (Z to A)'. | H19: N/A | I19: Product order reverses alphabetically (T-Shirt first, Backpack last) | J19: Order correctly reversed | K19: Pass | L19: Medium | M19: P2 | N19: Yes | O19: SauceDemoTest.land03_sortZtoA | P19: Pass
A20: LAND-04 | B20: SauceDemo | C20: Landing Page | D20: Dropdown (sort) | E20: User logged in, on Products page | F20: Sort by Price (low to high) | G20: 1. Click sort dropdown. 2. Select 'Price (low to high)'. | H20: N/A | I20: Products ordered ascending from $7.99 to $49.99 | J20: Order matched ascending price correctly | K20: Pass | L20: Medium | M20: P2 | N20: Yes | O20: SauceDemoTest.land04_sortPriceLowToHigh | P20: Pass
A21: LAND-05 | B21: SauceDemo | C21: Landing Page | D21: Dropdown (sort) | E21: User logged in, on Products page | F21: Sort by Price (high to low) | G21: 1. Click sort dropdown. 2. Select 'Price (high to low)'. | H21: N/A | I21: Products ordered descending from $49.99 to $7.99 | J21: Order matched descending price correctly | K21: Pass | L21: Medium | M21: P2 | N21: Yes | O21: SauceDemoTest.land05_sortPriceHighToLow | P21: Pass
A22: LAND-06 | B22: SauceDemo | C22: Landing Page | D22: Button (add/remove) | E22: User logged in, on Products page, item not yet in cart | F22: Add single item to cart | G22: 1. Click 'Add to cart' on Sauce Labs Backpack. | H22: N/A | I22: Button label changes to 'Remove'; cart icon badge shows '1' | J22: Confirmed: button changed to Remove, badge showed 1 | K22: Pass | L22: Critical | M22: P1 | N22: Yes | O22: SauceDemoTest.land06_addSingleItemToCart | P22: Pass
A23: LAND-07 | B23: SauceDemo | C23: Landing Page | D23: Button (add/remove) | E23: User logged in, on Products page, cart empty | F23: Add multiple items to cart | G23: 1. Click 'Add to cart' on Backpack. 2. Click 'Add to cart' on Bike Light. | H23: N/A | I23: Both buttons change to 'Remove'; cart badge shows '2' | J23: Badge correctly showed 2, both buttons updated | K23: Pass | L23: Critical | M23: P1 | N23: Yes | O23: SauceDemoTest.land07_addTwoItemsToCart | P23: Pass
A24: LAND-08 | B24: SauceDemo | C24: Landing Page | D24: Button (add/remove) | E24: User logged in, at least one item already in cart | F24: Remove item from cart (from Products page) | G24: 1. With an item in cart, click 'Remove' on that item's card. | H24: N/A | I24: Button reverts to 'Add to cart'; cart badge decrements by 1 | J24: Badge updated correctly, button reverted correctly | K24: Pass | L24: High | M24: P1 | N24: Yes | O24: SauceDemoTest.land08_removeItemFromProductsPage | P24: Pass
A25: LAND-09 | B25: SauceDemo | C25: Landing Page | D25: Icon link (cart) | E25: User logged in, at least one item in cart | F25: Cart icon navigation | G25: 1. Click the cart icon in the top right corner. | H25: N/A | I25: Navigates to /cart.html showing 'Your Cart' with correct item(s), quantity, price, Remove button, Continue Shopping & Checkout buttons | J25: Navigated correctly, showed correct item details | K25: Pass | L25: High | M25: P1 | N25: Yes | O25: SauceDemoTest.land09_cartIconNavigation | P25: Pass | Q25: Cart icon click sometimes required a precise click coordinate to register
A26: LAND-10 | B26: SauceDemo | C26: Landing Page | D26: Button | E26: User logged in, on cart page with item(s) | F26: Continue Shopping from cart | G26: 1. On cart page, click 'Continue Shopping'. | H26: N/A | I26: Navigates back to /inventory.html (Products page) | J26: Returned to Products page correctly | K26: Pass | L26: Medium | M26: P2 | N26: Yes | O26: SauceDemoTest.land10_continueShoppingFromCart | P26: Pass
A27: LAND-11 | B27: SauceDemo | C27: Landing Page | D27: Menu, button | E27: User logged in, on Products page | F27: Hamburger menu opens | G27: 1. Click hamburger icon (top left). | H27: N/A | I27: Side menu slides in showing: All Items, About, Logout, Reset App State, plus a Close (X) button | J27: All four links present and visible | K27: Pass | L27: Medium | M27: P2 | N27: Yes | O27: SauceDemoTest.land11_hamburgerMenuOpens | P27: Pass
A28: LAND-12 | B28: SauceDemo | C28: Landing Page | D28: Menu, button | E28: User logged in, at least one item in cart, menu open | F28: Reset App State | G28: 1. Open menu. 2. Click 'Reset App State'. | H28: N/A | I28: Cart badge clears to 0 AND all 'Remove' buttons revert to 'Add to cart' | J28: Cart badge cleared, but product's button still displayed 'Remove' instead of reverting until page refresh | K28: Fail (minor defect) | L28: Low | M28: P3 | N28: Yes | O28: SauceDemoTest.land12_resetAppState | P28: Pass (defect anchor) | Q28: UI inconsistency: button state not synced with cart badge after Reset App State
A29: LAND-13 | B29: SauceDemo | C29: Landing Page | D29: Menu, button | E29: User logged in, hamburger menu open | F29: Close menu (X button) | G29: 1. With menu open, click the 'X' close icon. | H29: N/A | I29: Menu slides closed, returns to normal page view | J29: Menu closed successfully | K29: Pass | L29: Low | M29: P3 | N29: Yes | O29: SauceDemoTest.land13_closeHamburgerMenu | P29: Pass
A30: LAND-14 | B30: SauceDemo | C30: Landing Page | D30: Link (footer) | E30: User logged in, on Products page, footer visible | F30: Footer social link - X (formerly Twitter) | G30: 1. Locate 'X' link in footer and inspect its href. | H30: N/A | I30: Link href points to Sauce Labs' official X page | J30: href="https://x.com/saucelabs" - correct | K30: Pass | L30: Low | M30: P3 | N30: Yes | O30: SauceDemoTest.land14_footerTwitterLink | P30: Pass | Q30: Link not clicked/navigated to avoid leaving the app domain. Site renamed the link from Twitter (social-twitter) to X (social-x); re-verified 2026-10-28
A31: LAND-15 | B31: SauceDemo | C31: Landing Page | D31: Link (footer) | E31: User logged in, on Products page, footer visible | F31: Footer social link - Facebook | G31: 1. Locate 'Facebook' link in footer and inspect its href. | H31: N/A | I31: Link href points to Sauce Labs' official Facebook page | J31: href="https://www.facebook.com/saucelabs" - correct | K31: Pass | L31: Low | M31: P3 | N31: Yes | O31: SauceDemoTest.land15_footerFacebookLink | P31: Pass | Q31: Link not clicked/navigated to avoid leaving the app domain
A32: LAND-16 | B32: SauceDemo | C32: Landing Page | D32: Link (footer) | E32: User logged in, on Products page, footer visible | F32: Footer social link - LinkedIn | G32: 1. Locate 'LinkedIn' link in footer and inspect its href. | H32: N/A | I32: Link href points to Sauce Labs' official LinkedIn page | J32: href="https://www.linkedin.com/company/sauce-labs/" - correct | K32: Pass | L32: Low | M32: P3 | N32: Yes | O32: SauceDemoTest.land16_footerLinkedInLink | P32: Pass | Q32: Link not clicked/navigated to avoid leaving the app domain
A33: LAND-17 | B33: SauceDemo | C33: Landing Page | D33: Menu link | E33: User logged in, hamburger menu open | F33: Logout functionality | G33: 1. Open hamburger menu. 2. Click 'Logout'. | H33: N/A | I33: Redirects to login page (saucedemo.com) and session/cart state ends | J33: Redirected to login page successfully, fields empty | K33: Pass | L33: Critical | M33: P1 | N33: Yes | O33: SauceDemoTest.land17_logout | P33: Pass | Q33: Cart contents were observed to persist in local/session storage across a subsequent login in later testing
A34: CART-01 | B34: SauceDemo | C34: Cart & Checkout | D34: Button | E34: User logged in, item added to cart | F34: Navigate to cart with item | G34: 1. Add 'Sauce Labs Onesie' to cart. 2. Click cart icon. | H34: N/A | I34: Navigates to /cart.html showing correct item, qty, price | J34: Correctly showed 1x Onesie, $7.99 | K34: Pass | L34: High | M34: P1 | N34: Yes | O34: SauceDemoTest.cart01_cartShowsCorrectItem | P34: Pass
A35: CART-02 | B35: SauceDemo | C35: Cart & Checkout | D35: Button | E35: User logged in, on cart page with item(s) | F35: Proceed to Checkout | G35: 1. On cart page, click 'Checkout'. | H35: N/A | I35: Navigates to /checkout-step-one.html with 'Checkout: Your Information' form | J35: Navigated correctly | K35: Pass | L35: Critical | M35: P1 | N35: Yes | O35: SauceDemoTest.cart02_proceedToCheckout | P35: Pass
A36: CART-03 | B36: SauceDemo | C36: Cart & Checkout | D36: Text input (checkout form), button | E36: User on checkout-step-one.html, all fields blank | F36: Checkout validation - empty First Name | G36: 1. Leave all fields blank. 2. Click 'Continue'. | H36: (blank) | I36: Error: 'First Name is required' | J36: Matched exactly | K36: Pass | L36: Medium | M36: P2 | N36: Yes | O36: SauceDemoTest.cart03_checkoutEmptyFirstName | P36: Pass
A37: CART-04 | B37: SauceDemo | C37: Cart & Checkout | D37: Text input (checkout form), button | E37: User on checkout-step-one.html, First Name filled only | F37: Checkout validation - empty Last Name | G37: 1. Fill First Name only. 2. Click 'Continue'. | H37: First Name = John | I37: Error: 'Last Name is required' | J37: Matched exactly | K37: Pass | L37: Medium | M37: P2 | N37: Yes | O37: SauceDemoTest.cart04_checkoutEmptyLastName | P37: Pass
A38: CART-05 | B38: SauceDemo | C38: Cart & Checkout | D38: Text input (checkout form), button | E38: User on checkout-step-one.html, First+Last Name filled | F38: Checkout validation - empty Postal Code | G38: 1. Fill First + Last Name. 2. Click 'Continue'. | H38: First=John, Last=Doe | I38: Error: 'Postal Code is required' | J38: Matched exactly | K38: Pass | L38: Medium | M38: P2 | N38: Yes | O38: SauceDemoTest.cart05_checkoutEmptyPostalCode | P38: Pass
A39: CART-06 | B39: SauceDemo | C39: Cart & Checkout | D39: Text input (checkout form), button | E39: User on checkout-step-one.html, all fields filled correctly | F39: Checkout step one success | G39: 1. Fill all 3 fields correctly. 2. Click 'Continue'. | H39: John / Doe / 12345 | I39: Navigates to /checkout-step-two.html (Overview) | J39: Navigated correctly | K39: Pass | L39: Critical | M39: P1 | N39: Yes | O39: SauceDemoTest.cart06_checkoutStepOneSuccess | P39: Pass
A40: CART-07 | B40: SauceDemo | C40: Cart & Checkout | D40: Read-only values (totals) | E40: User on checkout-step-two.html (Overview) with item(s) in cart | F40: Checkout overview totals accuracy | G40: 1. On Overview page, review Item total, Tax, and Total values against expected calculation. | H40: 1 item ($7.99); 3 items ($55.97 combined) | I40: Total = Item total + Tax, calculated correctly at ~8% tax rate | J40: Single item: $7.99 + $0.64 tax = $8.63 total. 3 items: $55.97 + $4.48 tax = $60.45 total. Both correct. | K40: Pass | L40: High | M40: P1 | N40: Yes | O40: SauceDemoTest.cart07_checkoutOverviewTotals | P40: Pass
...

Sheet Requirement Coverage
A1: Requirement Coverage
A2: Each requirement and the test cases that cover it.
A3: Requirement | B3: Where | C3: Test IDs | D3: Cases
A4: Add/edit form with multiple input types | B4: DemoQA Practice Form; SauceDemo checkout form | C4: FORM-01, CART-03, CART-04, CART-05, CART-06 | D4: 5
A5: Text input | B5: Login, checkout, Practice Form | C5: LOGIN-01, LOGIN-05, LOGIN-07, LOGIN-08, LOGIN-09, LOGIN-10, CART-06, FORM-01, FORM-02, FORM-05 | D5: 10
A6: Number input | B6: Practice Form mobile number | C6: FORM-03, FORM-04 | D6: 2
A7: Dropdown (single select) | B7: Product sort; Select Menu; date picker; State/City | C7: LAND-02, LAND-03, LAND-04, LAND-05, SEL-01, FORM-09, FORM-10 | D7: 7
A8: Multi-select | B8: Subjects autocomplete; native multi select | C8: FORM-06, SEL-02 | D8: 2
A9: Checkboxes | B9: Hobbies; checkbox tree | C9: FORM-07, CHK-01, CHK-02 | D9: 3
A10: Radio buttons | B10: Gender | C10: FORM-08 | D10: 1
A11: Buttons | B11: Login, cart, menu, checkout, DemoQA buttons | C11: LOGIN-12, LOGIN-13, LAND-06, LAND-07, LAND-08, LAND-10, LAND-11, LAND-13, CART-02, CART-08, CART-10, CART-11, BTN-01, BTN-02, BTN-03, FORM-11 | D11: 16
A12: Image upload | B12: Practice Form picture; Upload page | C12: FORM-01, FILE-01 | D12: 2
A13: Image / file download | B13: Upload and Download page; order PDF | C13: FILE-02, CART-14, CART-15 | D13: 3
A14: Negative and validation cases | B14: Login, checkout, Practice Form | C14: LOGIN-02, LOGIN-03, LOGIN-04, LOGIN-05, LOGIN-06, LOGIN-09, CART-03, CART-04, CART-05, CART-13, FORM-02, FORM-04, FORM-05 | D14: 13
A15: End-to-end flows | B15: Purchase; form submission | C15: CART-08, CART-09, FORM-01 | D15: 3

Sheet Defects
A1: Defects
A2: Each defect is kept as an automated regression anchor: the test asserts today's behavior and will fail when it changes.
A3: Defect | B3: Application | C3: Test ID | D3: Summary | E3: Steps to reproduce | F3: Expected | G3: Actual | H3: Severity | I3: Priority
A4: DEF-01 | B4: SauceDemo | C4: LAND-12 | D4: Reset App State | E4: 1. Open menu. 2. Click 'Reset App State'. | F4: Cart badge clears to 0 AND all 'Remove' buttons revert to 'Add to cart' | G4: Cart badge cleared, but product's button still displayed 'Remove' instead of reverting until page refresh | H4: Low | I4: P3
A5: DEF-02 | B5: SauceDemo | C5: CART-11 | D5: Cancel on checkout overview (step two) | E5: 1. From step two, click 'Cancel'. | F5: Returns to cart page (consistent with step-one Cancel), item preserved | G5: Returned directly to /inventory.html instead of /cart.html - inconsistent with step-one Cancel behavior | H5: Low | I5: P3
A6: DEF-03 | B6: SauceDemo | C6: CART-13 | D6: Checkout with empty cart | E6: 1. Ensure cart is empty. 2. Click 'Checkout' anyway. 3. Fill info form. 4. Click Finish. | F6: System should block checkout or display a 'cart is empty' message rather than allowing an order | G6: System allowed proceeding through the full checkout flow with $0.00 item total, $0.00 tax, and completed the order successfully with a confirmation page | H6: High | I6: P1
A7: DEF-04 | B7: DemoQA | C7: FORM-11 | D7: Close button dismisses modal | E7: 1. Submit a valid form. 2. Click Close. 3. Press Escape. | F7: Close dismisses the modal | G7: Close is clickable but modal stays open (native and JS click). Escape dismisses it. | H7: Medium | I7: P2
